<?xml version="1.0"?>
<robot name="transportino" xmlns:xacro="http://ros.org/wiki/xacro">

    <xacro:property name="pkg_folder" value="package://transportino_description/">
    
    </xacro:property>
    <xacro:property name="base_width" value="0.166"/>
    <xacro:property name="base_length" value="0.229685"/>
    <xacro:property name="base_height" value="0.097"/>

    <!-- All components positions are refered to the base link center point -->

    <xacro:property name="wheel_radius" value="0.0335"/>
    <xacro:property name="wheel_width" value="0.026"/>
    <xacro:property name="wheel_pos_x" value="-0.104393"/>
    <xacro:property name="wheel_pos_y" value="-0.032307"/>
    <xacro:property name="wheel_pos_z" value="0.025006"/>
 

    <xacro:property name="lidar_radius" value="0.032368"/>
    <xacro:property name="lidar_height" value="0.016"/>
    <xacro:property name="lidar_pos_x" value="0.0"/>
    <xacro:property name="lidar_pos_y" value="0.080404"/>
    <xacro:property name="lidar_pos_z" value="0.105"/>

    <link name="base_link">
        <visual>
            <geometry>
                <mesh filename="${pkg_folder}/meshes/base_link.stl" scale="0.001 0.001 0.001"/>
            </geometry>
            <material name="Cyan">
                <color rgba="0.0 1.0 1.0 1.0"/>
            </material>

        </visual>
    </link>

    <link name="base_footprint"></link>

    <joint name="base_joint" type="fixed">
        <origin xyz="0.0 0.0 ${-(wheel_pos_z - wheel_radius)}" rpy="0.0 0.0 0.0"/>
        <parent link="base_link"/>
        <child link="base_footprint"/>
    </joint>

    <xacro:macro name="wheel" params="prefix x_reflect">
        <link name="${prefix}_wheel_link">
            <visual>
                <origin rpy="${pi/2} 0.0 ${pi/2}"/>
                <geometry>
                    <cylinder radius="${wheel_radius}" length="${wheel_width}"/>
                </geometry>
                <material name="Gray">
                    <color rgba="0.5 0.5 0.5 1.0"/>
                </material>
            </visual>
        </link>

        <joint name="${prefix}_wheel_joint" type="continuous">
            <parent link="base_link"/>
            <child link="${prefix}_wheel_link"/>
            <origin xyz="${x_reflect * (wheel_pos_x)} ${wheel_pos_y} ${wheel_pos_z}"/>
            <axis xyz="1.0 0.0 0.0"/>
        </joint>
    </xacro:macro>

    <xacro:wheel prefix="left" x_reflect="1.0"/>
    <xacro:wheel prefix="right" x_reflect="-1.0"/>
    
    <link name="lidar_link">
        <visual>
            <geometry>
                <cylinder radius="${lidar_radius}" length="${lidar_height}"/>
            </geometry>
            <material name="Red">
                <color rgba="1.0 0.0 0.0 1.0"/>
            </material>
        </visual>
    </link>
    
    <joint name="lidar_joint" type="fixed">
        <origin xyz="${lidar_pos_x} ${lidar_pos_y} ${lidar_pos_z}" rpy="0.0 0.0 0.0"/>
        <parent link="base_link"/>
        <child link="lidar_link"/>
    </joint>

</robot>